/*
Vapor Test Suite
2010: Catch exception in subroutine

- output
Finally 1 executed.
Hello exception world.
Finally 2 executed.
*/

using Core;

class MyException: Exception
{
	public String message;

	public (String message)
	{
		this.message = message;
	}
}

class Test
{
	public static Func()
	{
		try
			throw new MyException("Hello exception world.");
		finally
			Console.WriteLine("Finally 1 executed.");
	}

	public static Main()
	{
		try
			Func();
		catch (MyException e)
			Console.WriteLine(e.message);
		finally
			Console.WriteLine("Finally 2 executed.");
	}
}
